const func = () =>{

try{
    let a = 0;
    console.log(program);
console.log("Program Run Successfully !");
}
catch(err){
    console.log(err);
}

finally{
    console.log("I am a good boy !!");

    // close the file 
    // Exite the perticular loop
    // Back To home 
}
}
func();
console.log("Hello world"); 
